Workbook

Sheet Tables
A1: CLK_CIRC_PORT_PODT | B1: =LOWER(A1) -> clk_circ_port_podt
A2: CLK_CIRC_RES_RSCB | B2: =LOWER(A2) -> clk_circ_res_rscb
A3: CLK_CIRC_RES_RSCV | B3: =LOWER(A3) -> clk_circ_res_rscv
A4: CLK_CIRC_RES_RSEV | B4: =LOWER(A4) -> clk_circ_res_rsev
A5: CLK_CIRD_NREL_NONO | B5: =LOWER(A5) -> clk_cird_nrel_nono
A6: CLK_CUST_CST_CUAD_RE | B6: =LOWER(A6) -> clk_cust_cst_cuad_re
A7: CLK_CUST_CST_CUDD | B7: =LOWER(A7) -> clk_cust_cst_cudd
A8: CLK_CUST_CST_CUEM | B8: =LOWER(A8) -> clk_cust_cst_cuem
A9: CLK_CUST_CST_CUNM_RE | B9: =LOWER(A9) -> clk_cust_cst_cunm_re
A10: CLK_CUST_CST_CUNO_RE | B10: =LOWER(A10) -> clk_cust_cst_cuno_re
A11: CLK_CUST_CST_CUOR | B11: =LOWER(A11) -> clk_cust_cst_cuor
A12: CLK_CUST_CST_CUPT | B12: =LOWER(A12) -> clk_cust_cst_cupt
... A60: CLK_LNK0_GLNK_CULD | B60: =LOWER(A60) -> clk_lnk0_glnk_culd

Sheet INCR
A1: Load Type | B1: Source System Name | C1: Table Name Source | D1: Table Name Target | E1: Column Name Source | F1: Column Name Target | G1: Data Type Source | H1: Data Type Target | I1: Format Target | J1: PrimaryKeyFlag | K1: PI | L1: Order | M1: Include Column | N1: Filter | O1: Transformation Required | P1: Tranformation Rule
A2: Incremental | B2: CLK | C2: CIRC_PORT_PODT | D2: CIRC_PORT_PODT | E2: EXTRACT_DATE | F2: EXTRACT_DATE | G2: DATE | H2: StringType() | I2: YYYY-MM-DD | L2: 1 | M2: Y | O2: Y | P2: CAST({COLREPLACE} AS STRING) | Q2: NULL
A3: Incremental | B3: CLK | C3: CIRC_PORT_PODT | D3: CIRC_PORT_PODT | E3: LOGICAL_DELETE_DATE | F3: LOGICAL_DELETE_DATE | G3: DATE | H3: StringType() | I3: YYYY-MM-DD | L3: 2 | M3: Y | O3: Y | P3: CAST({COLREPLACE} AS STRING) | Q3: NULL
A4: Incremental | B4: CLK | C4: CIRC_PORT_PODT | D4: CIRC_PORT_PODT | E4: ENVIRONMENT_ID | F4: ENVIRONMENT_ID | G4: CHAR(1) | H4: StringType() | J4: Y | L4: 3 | M4: Y | O4: Y | P4: CAST({COLREPLACE} AS STRING) | Q4: NULL
A5: Incremental | B5: CLK | C5: CIRC_PORT_PODT | D5: CIRC_PORT_PODT | E5: PERSON_ID | F5: PERSON_ID | G5: INTEGER | H5: StringType() | J5: Y | K5: Y | L5: 4 | M5: Y | O5: Y | P5: CAST({COLREPLACE} AS STRING) | Q5: NULL
A6: Incremental | B6: CLK | C6: CIRC_PORT_PODT | D6: CIRC_PORT_PODT | E6: PROCESSING_SEQUENCE | F6: PROCESSING_SEQUENCE | G6: SMALLINT | H6: StringType() | J6: Y | L6: 5 | M6: Y | O6: Y | P6: CAST({COLREPLACE} AS STRING) | Q6: NULL
A7: Incremental | B7: CLK | C7: CIRC_PORT_PODT | D7: CIRC_PORT_PODT | E7: PODT_AMR_1 | F7: PODT_AMR_1 | G7: CHAR(4) | H7: StringType() | L7: 6 | M7: Y | O7: Y | P7: CAST({COLREPLACE} AS STRING) | Q7: NULL
A8: Incremental | B8: CLK | C8: CIRC_PORT_PODT | D8: CIRC_PORT_PODT | E8: PODT_AMR_2 | F8: PODT_AMR_2 | G8: CHAR(1) | H8: StringType() | L8: 7 | M8: Y | O8: Y | P8: CAST({COLREPLACE} AS STRING) | Q8: NULL
A9: Incremental | B9: CLK | C9: CIRC_PORT_PODT | D9: CIRC_PORT_PODT | E9: PODT_AMR_3 | F9: PODT_AMR_3 | G9: CHAR(4) | H9: StringType() | L9: 8 | M9: Y | O9: Y | P9: CAST({COLREPLACE} AS STRING) | Q9: NULL
A10: Incremental | B10: CLK | C10: CIRC_PORT_PODT | D10: CIRC_PORT_PODT | E10: PODT_EXPCT_STAY_LEN_CODE | F10: PODT_EXPCT_STAY_LEN_CODE | G10: CHAR(3) | H10: StringType() | L10: 9 | M10: Y | O10: Y | P10: CAST({COLREPLACE} AS STRING) | Q10: NULL
A11: Incremental | B11: CLK | C11: CIRC_PORT_PODT | D11: CIRC_PORT_PODT | E11: PODT_AUS_DPRT_DATE | F11: PODT_AUS_DPRT_DATE | G11: INTEGER | H11: StringType() | I11: YYYY-MM-DD | L11: 10 | M11: Y | O11: Y | P11: CAST(CASE WHEN {COLREPLACE} = 0 THEN NULL ELSE COALESCE(TO_DATE(CONCAT(SUBSTR(CAST({COLREPLACE} AS STRING), 1, 4), '-', SUBSTR(CAST({COLREPLACE} AS STRING), 5, 2), '-', SUBSTR(CAST({COLREPLACE} AS STRING), 7, 2)), 'yyyy-MM-dd'),TO_DATE('3333-03-03', 'yyyy-MM-dd')) END AS STRING) | Q11: NULL
A12: Incremental | B12: CLK | C12: CIRC_PORT_PODT | D12: CIRC_PORT_PODT | E12: PODT_AUS_DPRT_DATE | F12: PODT_AUS_DPRT_DATE_ORIG | G12: INTEGER | H12: StringType() | L12: 11 | M12: Y | O12: Y | P12: CAST({COLREPLACE} AS STRING) | Q12: NULL
A13: Incremental | B13: CLK | C13: CIRC_PORT_PODT | D13: CIRC_PORT_PODT | E13: PODT_AUS_RTN_DATE | F13: PODT_AUS_RTN_DATE | G13: INTEGER | H13: StringType() | I13: YYYY-MM-DD | L13: 12 | M13: Y | O13: Y | P13: CAST(CASE WHEN {COLREPLACE} = 0 THEN NULL ELSE COALESCE(TO_DATE(CONCAT(SUBSTR(CAST({COLREPLACE} AS STRING), 1, 4), '-', SUBSTR(CAST({COLREPLACE} AS STRING), 5, 2), '-', SUBSTR(CAST({COLREPLACE} AS STRING), 7, 2)), 'yyyy-MM-dd'),TO_DATE('3333-03-03', 'yyyy-MM-dd')) END AS STRING) | Q13: NULL
A14: Incremental | B14: CLK | C14: CIRC_PORT_PODT | D14: CIRC_PORT_PODT | E14: PODT_AUS_RTN_DATE | F14: PODT_AUS_RTN_DATE_ORIG | G14: INTEGER | H14: StringType() | L14: 13 | M14: Y | O14: Y | P14: CAST({COLREPLACE} AS STRING) | Q14: NULL
A15: Incremental | B15: CLK | C15: CIRC_PORT_PODT | D15: CIRC_PORT_PODT | E15: PODT_DPRT_CERT_CODE | F15: PODT_DPRT_CERT_CODE | G15: CHAR(3) | H15: StringType() | L15: 14 | M15: Y | O15: Y | P15: CAST({COLREPLACE} AS STRING) | Q15: NULL
A16: Incremental | B16: CLK | C16: CIRC_PORT_PODT | D16: CIRC_PORT_PODT | E16: PODT_DOV | F16: PODT_DOV | G16: INTEGER | H16: StringType() | I16: YYYY-MM-DD | L16: 15 | M16: Y | O16: Y | P16: CAST(CASE WHEN {COLREPLACE} = 0 THEN NULL ELSE COALESCE(TO_DATE(CONCAT(SUBSTR(CAST({COLREPLACE} AS STRING), 1, 4), '-', SUBSTR(CAST({COLREPLACE} AS STRING), 5, 2), '-', SUBSTR(CAST({COLREPLACE} AS STRING), 7, 2)), 'yyyy-MM-dd'),TO_DATE('3333-03-03', 'yyyy-MM-dd')) END AS STRING) | Q16: NULL
A17: Incremental | B17: CLK | C17: CIRC_PORT_PODT | D17: CIRC_PORT_PODT | E17: PODT_DOV | F17: PODT_DOV_ORIG | G17: INTEGER | H17: StringType() | L17: 16 | M17: Y | O17: Y | P17: CAST({COLREPLACE} AS STRING) | Q17: NULL
A18: Incremental | B18: CLK | C18: CIRC_PORT_PODT | D18: CIRC_PORT_PODT | E18: PODT_LOCN_CTRY_CODE | F18: PODT_LOCN_CTRY_CODE | G18: CHAR(3) | H18: StringType() | L18: 17 | M18: Y | O18: Y | P18: CAST({COLREPLACE} AS STRING) | Q18: NULL
A19: Incremental | B19: CLK | C19: CIRC_PORT_PODT | D19: CIRC_PORT_PODT | E19: PODT_NZ_CLM_REJ_IND | F19: PODT_NZ_CLM_REJ_IND | G19: CHAR(1) | H19: StringType() | L19: 18 | M19: Y | O19: Y | P19: CAST({COLREPLACE} AS STRING) | Q19: NULL
A20: Incremental | B20: CLK | C20: CIRC_PORT_PODT | D20: CIRC_PORT_PODT | E20: PODT_OSEAS_CAN_EXEMPT_CODE | F20: PODT_OSEAS_CAN_EXEMPT_CODE | G20: CHAR(3) | H20: StringType() | L20: 19 | M20: Y | O20: Y | P20: CAST({COLREPLACE} AS STRING) | Q20: NULL
A21: Incremental | B21: CLK | C21: CIRC_PORT_PODT | D21: CIRC_PORT_PODT | E21: PODT_PRE_PP_SAVE_IND | F21: PODT_PRE_PP_SAVE_IND | G21: CHAR(1) | H21: StringType() | L21: 20 | M21: Y | O21: Y | P21: CAST({COLREPLACE} AS STRING) | Q21: NULL
A22: Incremental | B22: CLK | C22: CIRC_PORT_PODT | D22: CIRC_PORT_PODT | E22: PODT_SPCL_ACT_OF_GRACE_CODE | F22: PODT_SPCL_ACT_OF_GRACE_CODE | G22: CHAR(3) | H22: StringType() | L22: 21 | M22: Y | O22: Y | P22: CAST({COLREPLACE} AS STRING) | Q22: NULL
A23: Incremental | B23: CLK | C23: CIRC_PORT_PODT | D23: CIRC_PORT_PODT | E23: AMR1_RISL_DTS | F23: AMR1_RISL_DTS | G23: TIMESTAMP(6) | H23: StringType() | I23: YYYY-MM-DDBHH:MI:SS.S(6) | L23: 22 | M23: Y | O23: Y | P23: CAST({COLREPLACE} AS STRING) | Q23: NULL
A24: Incremental | B24: CLK | C24: CIRC_PORT_PODT | D24: CIRC_PORT_PODT | E24: AMR3_RISL_DTS | F24: AMR3_RISL_DTS | G24: TIMESTAMP(6) | H24: StringType() | I24: YYYY-MM-DDBHH:MI:SS.S(6) | L24: 23 | M24: Y | O24: Y | P24: CAST({COLREPLACE} AS STRING) | Q24: NULL
A25: Incremental | B25: CLK | C25: CIRC_PORT_PODT | D25: CIRC_PORT_PODT | E25: PARTY_ID | F25: PARTY_ID | G25: INTEGER | H25: StringType() | L25: 30 | M25: Y | O25: Y | P25: CAST({COLREPLACE} AS STRING) | Q25: NULL
A26: Incremental | B26: CLK | C26: CIRC_PORT_PODT | D26: CIRC_PORT_PODT | E26: PARTY_ROLE_ID | F26: PARTY_ROLE_ID | G26: INTEGER | H26: StringType() | L26: 31 | M26: Y | O26: Y | P26: CAST({COLREPLACE} AS STRING) | Q26: NULL
A27: Incremental | B27: CLK | C27: CIRC_PORT_PODT | D27: CIRC_PORT_PODT | E27: ERROR_COUNT | F27: ERROR_COUNT | G27: SMALLINT | H27: StringType() | L27: 32 | M27: Y | O27: Y | P27: CAST({COLREPLACE} AS STRING) | Q27: NULL
A28: Incremental | B28: CLK | C28: CIRC_RES_RSCB | D28: CIRC_RES_RSCB | E28: EXTRACT_DATE | F28: EXTRACT_DATE | G28: DATE | H28: StringType() | I28: YYYY-MM-DD | L28: 1 | M28: Y | O28: Y | P28: CAST({COLREPLACE} AS STRING) | Q28: NULL
A29: Incremental | B29: CLK | C29: CIRC_RES_RSCB | D29: CIRC_RES_RSCB | E29: LOGICAL_DELETE_DATE | F29: LOGICAL_DELETE_DATE | G29: DATE | H29: StringType() | I29: YYYY-MM-DD | L29: 2 | M29: Y | O29: Y | P29: CAST({COLREPLACE} AS STRING) | Q29: NULL
A30: Incremental | B30: CLK | C30: CIRC_RES_RSCB | D30: CIRC_RES_RSCB | E30: ENVIRONMENT_ID | F30: ENVIRONMENT_ID | G30: CHAR(1) | H30: StringType() | J30: Y | L30: 3 | M30: Y | O30: Y | P30: CAST({COLREPLACE} AS STRING) | Q30: NULL
A31: Incremental | B31: CLK | C31: CIRC_RES_RSCB | D31: CIRC_RES_RSCB | E31: PERSON_ID | F31: PERSON_ID | G31: INTEGER | H31: StringType() | J31: Y | K31: Y | L31: 4 | M31: Y | O31: Y | P31: CAST({COLREPLACE} AS STRING) | Q31: NULL
A32: Incremental | B32: CLK | C32: CIRC_RES_RSCB | D32: CIRC_RES_RSCB | E32: RSCB_DOR | F32: RSCB_DOR | G32: INTEGER | H32: StringType() | I32: YYYY-MM-DD | L32: 5 | M32: Y | O32: Y | P32: CAST(CASE WHEN {COLREPLACE} = 0 THEN NULL ELSE COALESCE(TO_DATE(CONCAT(SUBSTR(CAST({COLREPLACE} AS STRING), 1, 4), '-', SUBSTR(CAST({COLREPLACE} AS STRING), 5, 2), '-', SUBSTR(CAST({COLREPLACE} AS STRING), 7, 2)), 'yyyy-MM-dd'),TO_DATE('3333-03-03', 'yyyy-MM-dd')) END AS STRING) | Q32: NULL
A33: Incremental | B33: CLK | C33: CIRC_RES_RSCB | D33: CIRC_RES_RSCB | E33: RSCB_DOR | F33: RSCB_DOR_ORIG | G33: INTEGER | H33: StringType() | L33: 6 | M33: Y | O33: Y | P33: CAST({COLREPLACE} AS STRING) | Q33: NULL
A34: Incremental | B34: CLK | C34: CIRC_RES_RSCB | D34: CIRC_RES_RSCB | E34: PROCESSING_SEQUENCE | F34: PROCESSING_SEQUENCE | G34: SMALLINT | H34: StringType() | J34: Y | L34: 7 | M34: Y | O34: Y | P34: CAST({COLREPLACE} AS STRING) | Q34: NULL
A35: Incremental | B35: CLK | C35: CIRC_RES_RSCB | D35: CIRC_RES_RSCB | E35: RSCB_AMR_1 | F35: RSCB_AMR_1 | G35: CHAR(4) | H35: StringType() | L35: 8 | M35: Y | O35: Y | P35: CAST({COLREPLACE} AS STRING) | Q35: NULL
A36: Incremental | B36: CLK | C36: CIRC_RES_RSCB | D36: CIRC_RES_RSCB | E36: RSCB_AMR_2 | F36: RSCB_AMR_2 | G36: CHAR(1) | H36: StringType() | L36: 9 | M36: Y | O36: Y | P36: CAST({COLREPLACE} AS STRING) | Q36: NULL
A37: Incremental | B37: CLK | C37: CIRC_RES_RSCB | D37: CIRC_RES_RSCB | E37: RSCB_AMR_3 | F37: RSCB_AMR_3 | G37: CHAR(4) | H37: StringType() | L37: 10 | M37: Y | O37: Y | P37: CAST({COLREPLACE} AS STRING) | Q37: NULL
A38: Incremental | B38: CLK | C38: CIRC_RES_RSCB | D38: CIRC_RES_RSCB | E38: RSCB_BIRTH_CTRY_CODE | F38: RSCB_BIRTH_CTRY_CODE | G38: CHAR(2) | H38: StringType() | L38: 11 | M38: Y | O38: Y | P38: CAST({COLREPLACE} AS STRING) | Q38: NULL
A39: Incremental | B39: CLK | C39: CIRC_RES_RSCB | D39: CIRC_RES_RSCB | E39: RSCB_CHNL_CODE | F39: RSCB_CHNL_CODE | G39: CHAR(3) | H39: StringType() | L39: 12 | M39: Y | O39: Y | P39: CAST({COLREPLACE} AS STRING) | Q39: NULL
A40: Incremental | B40: CLK | C40: CIRC_RES_RSCB | D40: CIRC_RES_RSCB | E40: AMR1_RISL_DTS | F40: AMR1_RISL_DTS | G40: TIMESTAMP(6) | H40: StringType() | I40: YYYY-MM-DDBHH:MI:SS.S(6) | L40: 13 | M40: Y | O40: Y | P40: CAST({COLREPLACE} AS STRING) | Q40: NULL
...

Sheet ETLMetadata
A1: Load Type | B1: Source System Name | C1: Table Name Source | D1: Table Name Target | E1: Column Name Source | F1: Column Name Target | G1: Data Type Source | H1: Data Type Target | I1: Format Target | J1: PrimaryKeyFlag | K1: PI | L1: Order | M1: Include Column | N1: Filter | O1: Transformation Required | P1: Tranformation Rule
A2: History | B2: CLK | C2: CIRC_PORT_PODT | D2: CIRC_PORT_PODT | E2: EXTRACT_DATE | F2: EXTRACT_DATE | G2: DATE | H2: StringType() | I2: YYYY-MM-DD | L2: 1 | M2: Y | O2: Y | P2: CAST({COLREPLACE} AS STRING)
A3: History | B3: CLK | C3: CIRC_PORT_PODT | D3: CIRC_PORT_PODT | E3: LOGICAL_DELETE_DATE | F3: LOGICAL_DELETE_DATE | G3: DATE | H3: StringType() | I3: YYYY-MM-DD | L3: 2 | M3: Y | O3: Y | P3: CAST({COLREPLACE} AS STRING)
A4: History | B4: CLK | C4: CIRC_PORT_PODT | D4: CIRC_PORT_PODT | E4: ENVIRONMENT_ID | F4: ENVIRONMENT_ID | G4: CHAR(1) | H4: StringType() | J4: Y | L4: 3 | M4: Y | O4: Y | P4: CAST({COLREPLACE} AS STRING)
A5: History | B5: CLK | C5: CIRC_PORT_PODT | D5: CIRC_PORT_PODT | E5: PERSON_ID | F5: PERSON_ID | G5: INTEGER | H5: StringType() | J5: Y | K5: Y | L5: 4 | M5: Y | O5: Y | P5: CAST({COLREPLACE} AS STRING)
A6: History | B6: CLK | C6: CIRC_PORT_PODT | D6: CIRC_PORT_PODT | E6: PROCESSING_SEQUENCE | F6: PROCESSING_SEQUENCE | G6: SMALLINT | H6: StringType() | J6: Y | L6: 5 | M6: Y | O6: Y | P6: CAST({COLREPLACE} AS STRING)
A7: History | B7: CLK | C7: CIRC_PORT_PODT | D7: CIRC_PORT_PODT | E7: PODT_AMR_1 | F7: PODT_AMR_1 | G7: CHAR(4) | H7: StringType() | L7: 6 | M7: Y | O7: Y | P7: CAST({COLREPLACE} AS STRING)
A8: History | B8: CLK | C8: CIRC_PORT_PODT | D8: CIRC_PORT_PODT | E8: PODT_AMR_2 | F8: PODT_AMR_2 | G8: CHAR(1) | H8: StringType() | L8: 7 | M8: Y | O8: Y | P8: CAST({COLREPLACE} AS STRING)
A9: History | B9: CLK | C9: CIRC_PORT_PODT | D9: CIRC_PORT_PODT | E9: PODT_AMR_3 | F9: PODT_AMR_3 | G9: CHAR(4) | H9: StringType() | L9: 8 | M9: Y | O9: Y | P9: CAST({COLREPLACE} AS STRING)
A10: History | B10: CLK | C10: CIRC_PORT_PODT | D10: CIRC_PORT_PODT | E10: PODT_EXPCT_STAY_LEN_CODE | F10: PODT_EXPCT_STAY_LEN_CODE | G10: CHAR(3) | H10: StringType() | L10: 9 | M10: Y | O10: Y | P10: CAST({COLREPLACE} AS STRING)
A11: History | B11: CLK | C11: CIRC_PORT_PODT | D11: CIRC_PORT_PODT | E11: PODT_AUS_DPRT_DATE | F11: PODT_AUS_DPRT_DATE | G11: DATE | H11: StringType() | I11: YYYY-MM-DD | L11: 10 | M11: Y | O11: Y | P11: CAST({COLREPLACE} AS STRING)
A12: History | B12: CLK | C12: CIRC_PORT_PODT | D12: CIRC_PORT_PODT | E12: PODT_AUS_DPRT_DATE_ORIG | F12: PODT_AUS_DPRT_DATE_ORIG | G12: INTEGER | H12: StringType() | L12: 11 | M12: Y | O12: Y | P12: CAST({COLREPLACE} AS STRING)
A13: History | B13: CLK | C13: CIRC_PORT_PODT | D13: CIRC_PORT_PODT | E13: PODT_AUS_RTN_DATE | F13: PODT_AUS_RTN_DATE | G13: DATE | H13: StringType() | I13: YYYY-MM-DD | L13: 12 | M13: Y | O13: Y | P13: CAST({COLREPLACE} AS STRING)
A14: History | B14: CLK | C14: CIRC_PORT_PODT | D14: CIRC_PORT_PODT | E14: PODT_AUS_RTN_DATE_ORIG | F14: PODT_AUS_RTN_DATE_ORIG | G14: INTEGER | H14: StringType() | L14: 13 | M14: Y | O14: Y | P14: CAST({COLREPLACE} AS STRING)
A15: History | B15: CLK | C15: CIRC_PORT_PODT | D15: CIRC_PORT_PODT | E15: PODT_DPRT_CERT_CODE | F15: PODT_DPRT_CERT_CODE | G15: CHAR(3) | H15: StringType() | L15: 14 | M15: Y | O15: Y | P15: CAST({COLREPLACE} AS STRING)
A16: History | B16: CLK | C16: CIRC_PORT_PODT | D16: CIRC_PORT_PODT | E16: PODT_DOV | F16: PODT_DOV | G16: DATE | H16: StringType() | I16: YYYY-MM-DD | L16: 15 | M16: Y | O16: Y | P16: CAST({COLREPLACE} AS STRING)
A17: History | B17: CLK | C17: CIRC_PORT_PODT | D17: CIRC_PORT_PODT | E17: PODT_DOV_ORIG | F17: PODT_DOV_ORIG | G17: INTEGER | H17: StringType() | L17: 16 | M17: Y | O17: Y | P17: CAST({COLREPLACE} AS STRING)
A18: History | B18: CLK | C18: CIRC_PORT_PODT | D18: CIRC_PORT_PODT | E18: PODT_LOCN_CTRY_CODE | F18: PODT_LOCN_CTRY_CODE | G18: CHAR(3) | H18: StringType() | L18: 17 | M18: Y | O18: Y | P18: CAST({COLREPLACE} AS STRING)
A19: History | B19: CLK | C19: CIRC_PORT_PODT | D19: CIRC_PORT_PODT | E19: PODT_NZ_CLM_REJ_IND | F19: PODT_NZ_CLM_REJ_IND | G19: CHAR(1) | H19: StringType() | L19: 18 | M19: Y | O19: Y | P19: CAST({COLREPLACE} AS STRING)
A20: History | B20: CLK | C20: CIRC_PORT_PODT | D20: CIRC_PORT_PODT | E20: PODT_OSEAS_CAN_EXEMPT_CODE | F20: PODT_OSEAS_CAN_EXEMPT_CODE | G20: CHAR(3) | H20: StringType() | L20: 19 | M20: Y | O20: Y | P20: CAST({COLREPLACE} AS STRING)
A21: History | B21: CLK | C21: CIRC_PORT_PODT | D21: CIRC_PORT_PODT | E21: PODT_PRE_PP_SAVE_IND | F21: PODT_PRE_PP_SAVE_IND | G21: CHAR(1) | H21: StringType() | L21: 20 | M21: Y | O21: Y | P21: CAST({COLREPLACE} AS STRING)
A22: History | B22: CLK | C22: CIRC_PORT_PODT | D22: CIRC_PORT_PODT | E22: PODT_SPCL_ACT_OF_GRACE_CODE | F22: PODT_SPCL_ACT_OF_GRACE_CODE | G22: CHAR(3) | H22: StringType() | L22: 21 | M22: Y | O22: Y | P22: CAST({COLREPLACE} AS STRING)
A23: History | B23: CLK | C23: CIRC_PORT_PODT | D23: CIRC_PORT_PODT | E23: AMR1_RISL_DTS | F23: AMR1_RISL_DTS | G23: TIMESTAMP(6) | H23: StringType() | I23: YYYY-MM-DDBHH:MI:SS.S(6) | L23: 22 | M23: Y | O23: Y | P23: CAST({COLREPLACE} AS STRING)
A24: History | B24: CLK | C24: CIRC_PORT_PODT | D24: CIRC_PORT_PODT | E24: AMR3_RISL_DTS | F24: AMR3_RISL_DTS | G24: TIMESTAMP(6) | H24: StringType() | I24: YYYY-MM-DDBHH:MI:SS.S(6) | L24: 23 | M24: Y | O24: Y | P24: CAST({COLREPLACE} AS STRING)
A25: History | B25: CLK | C25: CIRC_PORT_PODT | D25: CIRC_PORT_PODT | E25: PARTY_ID | F25: PARTY_ID | G25: INTEGER | H25: StringType() | L25: 30 | M25: Y | O25: Y | P25: CAST({COLREPLACE} AS STRING)
A26: History | B26: CLK | C26: CIRC_PORT_PODT | D26: CIRC_PORT_PODT | E26: PARTY_ROLE_ID | F26: PARTY_ROLE_ID | G26: INTEGER | H26: StringType() | L26: 31 | M26: Y | O26: Y | P26: CAST({COLREPLACE} AS STRING)
A27: History | B27: CLK | C27: CIRC_PORT_PODT | D27: CIRC_PORT_PODT | E27: ERROR_COUNT | F27: ERROR_COUNT | G27: SMALLINT | H27: StringType() | L27: 32 | M27: Y | O27: Y | P27: CAST({COLREPLACE} AS STRING)
A28: History | B28: CLK | C28: CIRC_PORT_PODT | D28: CIRC_PORT_PODT | E28: Start_Date | F28: Start_Date | G28: DATE | H28: StringType() | I28: YYYY-MM-DD | L28: 33 | M28: Y | O28: Y | P28: CAST({COLREPLACE} AS STRING)
A29: History | B29: CLK | C29: CIRC_PORT_PODT | D29: CIRC_PORT_PODT | E29: End_Date | F29: End_Date | G29: DATE | H29: StringType() | I29: YYYY-MM-DD | L29: 34 | M29: Y | O29: Y | P29: CAST({COLREPLACE} AS STRING)
A30: History | B30: CLK | C30: CIRC_PORT_PODT | D30: CIRC_PORT_PODT | E30: Record_Deleted_Flag | F30: Record_Deleted_Flag | G30: BYTEINT | H30: StringType() | L30: 35 | M30: Y | O30: Y | P30: CAST({COLREPLACE} AS STRING)
A31: History | B31: CLK | C31: CIRC_RES_RSCB | D31: CIRC_RES_RSCB | E31: EXTRACT_DATE | F31: EXTRACT_DATE | G31: DATE | H31: StringType() | I31: YYYY-MM-DD | L31: 1 | M31: Y | O31: Y | P31: CAST({COLREPLACE} AS STRING)
A32: History | B32: CLK | C32: CIRC_RES_RSCB | D32: CIRC_RES_RSCB | E32: LOGICAL_DELETE_DATE | F32: LOGICAL_DELETE_DATE | G32: DATE | H32: StringType() | I32: YYYY-MM-DD | L32: 2 | M32: Y | O32: Y | P32: CAST({COLREPLACE} AS STRING)
A33: History | B33: CLK | C33: CIRC_RES_RSCB | D33: CIRC_RES_RSCB | E33: ENVIRONMENT_ID | F33: ENVIRONMENT_ID | G33: CHAR(1) | H33: StringType() | J33: Y | L33: 3 | M33: Y | O33: Y | P33: CAST({COLREPLACE} AS STRING)
A34: History | B34: CLK | C34: CIRC_RES_RSCB | D34: CIRC_RES_RSCB | E34: PERSON_ID | F34: PERSON_ID | G34: INTEGER | H34: StringType() | J34: Y | K34: Y | L34: 4 | M34: Y | O34: Y | P34: CAST({COLREPLACE} AS STRING)
A35: History | B35: CLK | C35: CIRC_RES_RSCB | D35: CIRC_RES_RSCB | E35: RSCB_DOR | F35: RSCB_DOR | G35: DATE | H35: StringType() | I35: YYYY-MM-DD | L35: 5 | M35: Y | O35: Y | P35: CAST({COLREPLACE} AS STRING)
A36: History | B36: CLK | C36: CIRC_RES_RSCB | D36: CIRC_RES_RSCB | E36: RSCB_DOR_ORIG | F36: RSCB_DOR_ORIG | G36: INTEGER | H36: StringType() | L36: 6 | M36: Y | O36: Y | P36: CAST({COLREPLACE} AS STRING)
A37: History | B37: CLK | C37: CIRC_RES_RSCB | D37: CIRC_RES_RSCB | E37: PROCESSING_SEQUENCE | F37: PROCESSING_SEQUENCE | G37: SMALLINT | H37: StringType() | J37: Y | L37: 7 | M37: Y | O37: Y | P37: CAST({COLREPLACE} AS STRING)
A38: History | B38: CLK | C38: CIRC_RES_RSCB | D38: CIRC_RES_RSCB | E38: RSCB_AMR_1 | F38: RSCB_AMR_1 | G38: CHAR(4) | H38: StringType() | L38: 8 | M38: Y | O38: Y | P38: CAST({COLREPLACE} AS STRING)
A39: History | B39: CLK | C39: CIRC_RES_RSCB | D39: CIRC_RES_RSCB | E39: RSCB_AMR_2 | F39: RSCB_AMR_2 | G39: CHAR(1) | H39: StringType() | L39: 9 | M39: Y | O39: Y | P39: CAST({COLREPLACE} AS STRING)
A40: History | B40: CLK | C40: CIRC_RES_RSCB | D40: CIRC_RES_RSCB | E40: RSCB_AMR_3 | F40: RSCB_AMR_3 | G40: CHAR(4) | H40: StringType() | L40: 10 | M40: Y | O40: Y | P40: CAST({COLREPLACE} AS STRING)
...

Sheet Classification
A1: Table Name Source | B1: Column Name Source | C1: PrimaryKeyFlag | D1: Data Type Source | E1: Character Set | G1: Source Security Classification | H1: Description | I1: EDW Security Classification ID | J1: Start Date | K1: End Date | L1: Generated Metadata SQL
A2: =ETLMetadata!$C2 -> CIRC_PORT_PODT | B2: =ETLMetadata!$E2 -> EXTRACT_DATE | C2: =IF(ISBLANK(ETLMetadata!$J2), "", ETLMetadata!$J2) | D2: =ETLMetadata!$G2 -> DATE | G2: =UPPER($F2) | J2: 45952 | K2: 2958465 | L2: =CONCATENATE("INSERT INTO metadata_reference.file_schema VALUES('",TRIM(A2),"','",TRIM(B2),"',",IF(TRIM(C2)="","NULL","'"&TRIM(C2)&"'"),",'",TRIM(D2),"',",IF(TRIM(E2)="","NULL","'"&TRIM(E2)&"'"),",",IF(TRIM(G2)="","NULL","'"&TRIM(G2)&"'"),",",IF(TRIM(H2)="","NULL","'"&TRIM(H2)&"'"),",", IF(TRIM(I2)="","NULL",TRIM(I2)),",",IF(TRIM(J2)="","NULL","'"&TEXT(J2,"yyyy-mm-dd")&"'"),",",IF(TRIM(K2)="","NULL","'"&TEXT(K2,"yyyy-mm-dd")&"'"),",","USER, CURRENT_TIMESTAMP(0));") -> INSERT INTO metadata_reference.file_schema VALUES('CIRC_PORT_PODT','EXTRACT_DATE',NULL,'DATE',NULL,NULL,NULL,NULL,'2025-10-22','9999-12-31',USER, CURRENT_TIMESTAMP(0));
A3: =ETLMetadata!$C3 -> CIRC_PORT_PODT | B3: =ETLMetadata!$E3 -> LOGICAL_DELETE_DATE | C3: =IF(ISBLANK(ETLMetadata!$J3), "", ETLMetadata!$J3) | D3: =ETLMetadata!$G3 -> DATE | G3: =UPPER($F3) | J3: 45952 | K3: 2958465 | L3: =CONCATENATE("INSERT INTO metadata_reference.file_schema VALUES('",TRIM(A3),"','",TRIM(B3),"',",IF(TRIM(C3)="","NULL","'"&TRIM(C3)&"'"),",'",TRIM(D3),"',",IF(TRIM(E3)="","NULL","'"&TRIM(E3)&"'"),",",IF(TRIM(G3)="","NULL","'"&TRIM(G3)&"'"),",",IF(TRIM(H3)="","NULL","'"&TRIM(H3)&"'"),",", IF(TRIM(I3)="","NULL",TRIM(I3)),",",IF(TRIM(J3)="","NULL","'"&TEXT(J3,"yyyy-mm-dd")&"'"),",",IF(TRIM(K3)="","NULL","'"&TEXT(K3,"yyyy-mm-dd")&"'"),",","USER, CURRENT_TIMESTAMP(0));") -> INSERT INTO metadata_reference.file_schema VALUES('CIRC_PORT_PODT','LOGICAL_DELETE_DATE',NULL,'DATE',NULL,NULL,NULL,NULL,'2025-10-22','9999-12-31',USER, CURRENT_TIMESTAMP(0));
A4: =ETLMetadata!$C4 -> CIRC_PORT_PODT | B4: =ETLMetadata!$E4 -> ENVIRONMENT_ID | C4: =IF(ISBLANK(ETLMetadata!$J4), "", ETLMetadata!$J4) -> Y | D4: =ETLMetadata!$G4 -> CHAR(1) | G4: =UPPER($F4) | J4: 45952 | K4: 2958465 | L4: =CONCATENATE("INSERT INTO metadata_reference.file_schema VALUES('",TRIM(A4),"','",TRIM(B4),"',",IF(TRIM(C4)="","NULL","'"&TRIM(C4)&"'"),",'",TRIM(D4),"',",IF(TRIM(E4)="","NULL","'"&TRIM(E4)&"'"),",",IF(TRIM(G4)="","NULL","'"&TRIM(G4)&"'"),",",IF(TRIM(H4)="","NULL","'"&TRIM(H4)&"'"),",", IF(TRIM(I4)="","NULL",TRIM(I4)),",",IF(TRIM(J4)="","NULL","'"&TEXT(J4,"yyyy-mm-dd")&"'"),",",IF(TRIM(K4)="","NULL","'"&TEXT(K4,"yyyy-mm-dd")&"'"),",","USER, CURRENT_TIMESTAMP(0));") -> INSERT INTO metadata_reference.file_schema VALUES('CIRC_PORT_PODT','ENVIRONMENT_ID','Y','CHAR(1)',NULL,NULL,NULL,NULL,'2025-10-22','9999-12-31',USER, CURRENT_TIMESTAMP(0));
A5: =ETLMetadata!$C5 -> CIRC_PORT_PODT | B5: =ETLMetadata!$E5 -> PERSON_ID | C5: =IF(ISBLANK(ETLMetadata!$J5), "", ETLMetadata!$J5) -> Y | D5: =ETLMetadata!$G5 -> INTEGER | F5: Personal_IdentityInfoDirect | G5: =UPPER($F5) -> PERSONAL_IDENTITYINFODIRECT | J5: 45952 | K5: 2958465 | L5: =CONCATENATE("INSERT INTO metadata_reference.file_schema VALUES('",TRIM(A5),"','",TRIM(B5),"',",IF(TRIM(C5)="","NULL","'"&TRIM(C5)&"'"),",'",TRIM(D5),"',",IF(TRIM(E5)="","NULL","'"&TRIM(E5)&"'"),",",IF(TRIM(G5)="","NULL","'"&TRIM(G5)&"'"),",",IF(TRIM(H5)="","NULL","'"&TRIM(H5)&"'"),",", IF(TRIM(I5)="","NULL",TRIM(I5)),",",IF(TRIM(J5)="","NULL","'"&TEXT(J5,"yyyy-mm-dd")&"'"),",",IF(TRIM(K5)="","NULL","'"&TEXT(K5,"yyyy-mm-dd")&"'"),",","USER, CURRENT_TIMESTAMP(0));") -> INSERT INTO metadata_reference.file_schema VALUES('CIRC_PORT_PODT','PERSON_ID','Y','INTEGER',NULL,'PERSONAL_IDENTITYINFODIRECT ',NULL,NULL,'2025-10-22','9999-12-31',USER, CURRENT_TIMESTAMP(0));
A6: =ETLMetadata!$C6 -> CIRC_PORT_PODT | B6: =ETLMetadata!$E6 -> PROCESSING_SEQUENCE | C6: =IF(ISBLANK(ETLMetadata!$J6), "", ETLMetadata!$J6) -> Y | D6: =ETLMetadata!$G6 -> SMALLINT | G6: =UPPER($F6) | J6: 45952 | K6: 2958465 | L6: =CONCATENATE("INSERT INTO metadata_reference.file_schema VALUES('",TRIM(A6),"','",TRIM(B6),"',",IF(TRIM(C6)="","NULL","'"&TRIM(C6)&"'"),",'",TRIM(D6),"',",IF(TRIM(E6)="","NULL","'"&TRIM(E6)&"'"),",",IF(TRIM(G6)="","NULL","'"&TRIM(G6)&"'"),",",IF(TRIM(H6)="","NULL","'"&TRIM(H6)&"'"),",", IF(TRIM(I6)="","NULL",TRIM(I6)),",",IF(TRIM(J6)="","NULL","'"&TEXT(J6,"yyyy-mm-dd")&"'"),",",IF(TRIM(K6)="","NULL","'"&TEXT(K6,"yyyy-mm-dd")&"'"),",","USER, CURRENT_TIMESTAMP(0));") -> INSERT INTO metadata_reference.file_schema VALUES('CIRC_PORT_PODT','PROCESSING_SEQUENCE','Y','SMALLINT',NULL,NULL,NULL,NULL,'2025-10-22','9999-12-31',USER, CURRENT_TIMESTAMP(0));
A7: =ETLMetadata!$C7 -> CIRC_PORT_PODT | B7: =ETLMetadata!$E7 -> PODT_AMR_1 | C7: =IF(ISBLANK(ETLMetadata!$J7), "", ETLMetadata!$J7) | D7: =ETLMetadata!$G7 -> CHAR(4) | G7: =UPPER($F7) | J7: 45952 | K7: 2958465 | L7: =CONCATENATE("INSERT INTO metadata_reference.file_schema VALUES('",TRIM(A7),"','",TRIM(B7),"',",IF(TRIM(C7)="","NULL","'"&TRIM(C7)&"'"),",'",TRIM(D7),"',",IF(TRIM(E7)="","NULL","'"&TRIM(E7)&"'"),",",IF(TRIM(G7)="","NULL","'"&TRIM(G7)&"'"),",",IF(TRIM(H7)="","NULL","'"&TRIM(H7)&"'"),",", IF(TRIM(I7)="","NULL",TRIM(I7)),",",IF(TRIM(J7)="","NULL","'"&TEXT(J7,"yyyy-mm-dd")&"'"),",",IF(TRIM(K7)="","NULL","'"&TEXT(K7,"yyyy-mm-dd")&"'"),",","USER, CURRENT_TIMESTAMP(0));") -> INSERT INTO metadata_reference.file_schema VALUES('CIRC_PORT_PODT','PODT_AMR_1',NULL,'CHAR(4)',NULL,NULL,NULL,NULL,'2025-10-22','9999-12-31',USER, CURRENT_TIMESTAMP(0));
A8: =ETLMetadata!$C8 -> CIRC_PORT_PODT | B8: =ETLMetadata!$E8 -> PODT_AMR_2 | C8: =IF(ISBLANK(ETLMetadata!$J8), "", ETLMetadata!$J8) | D8: =ETLMetadata!$G8 -> CHAR(1) | G8: =UPPER($F8) | J8: 45952 | K8: 2958465 | L8: =CONCATENATE("INSERT INTO metadata_reference.file_schema VALUES('",TRIM(A8),"','",TRIM(B8),"',",IF(TRIM(C8)="","NULL","'"&TRIM(C8)&"'"),",'",TRIM(D8),"',",IF(TRIM(E8)="","NULL","'"&TRIM(E8)&"'"),",",IF(TRIM(G8)="","NULL","'"&TRIM(G8)&"'"),",",IF(TRIM(H8)="","NULL","'"&TRIM(H8)&"'"),",", IF(TRIM(I8)="","NULL",TRIM(I8)),",",IF(TRIM(J8)="","NULL","'"&TEXT(J8,"yyyy-mm-dd")&"'"),",",IF(TRIM(K8)="","NULL","'"&TEXT(K8,"yyyy-mm-dd")&"'"),",","USER, CURRENT_TIMESTAMP(0));") -> INSERT INTO metadata_reference.file_schema VALUES('CIRC_PORT_PODT','PODT_AMR_2',NULL,'CHAR(1)',NULL,NULL,NULL,NULL,'2025-10-22','9999-12-31',USER, CURRENT_TIMESTAMP(0));
A9: =ETLMetadata!$C9 -> CIRC_PORT_PODT | B9: =ETLMetadata!$E9 -> PODT_AMR_3 | C9: =IF(ISBLANK(ETLMetadata!$J9), "", ETLMetadata!$J9) | D9: =ETLMetadata!$G9 -> CHAR(4) | G9: =UPPER($F9) | J9: 45952 | K9: 2958465 | L9: =CONCATENATE("INSERT INTO metadata_reference.file_schema VALUES('",TRIM(A9),"','",TRIM(B9),"',",IF(TRIM(C9)="","NULL","'"&TRIM(C9)&"'"),",'",TRIM(D9),"',",IF(TRIM(E9)="","NULL","'"&TRIM(E9)&"'"),",",IF(TRIM(G9)="","NULL","'"&TRIM(G9)&"'"),",",IF(TRIM(H9)="","NULL","'"&TRIM(H9)&"'"),",", IF(TRIM(I9)="","NULL",TRIM(I9)),",",IF(TRIM(J9)="","NULL","'"&TEXT(J9,"yyyy-mm-dd")&"'"),",",IF(TRIM(K9)="","NULL","'"&TEXT(K9,"yyyy-mm-dd")&"'"),",","USER, CURRENT_TIMESTAMP(0));") -> INSERT INTO metadata_reference.file_schema VALUES('CIRC_PORT_PODT','PODT_AMR_3',NULL,'CHAR(4)',NULL,NULL,NULL,NULL,'2025-10-22','9999-12-31',USER, CURRENT_TIMESTAMP(0));
A10: =ETLMetadata!$C10 -> CIRC_PORT_PODT | B10: =ETLMetadata!$E10 -> PODT_EXPCT_STAY_LEN_CODE | C10: =IF(ISBLANK(ETLMetadata!$J10), "", ETLMetadata!$J10) | D10: =ETLMetadata!$G10 -> CHAR(3) | G10: =UPPER($F10) | J10: 45952 | K10: 2958465 | L10: =CONCATENATE("INSERT INTO metadata_reference.file_schema VALUES('",TRIM(A10),"','",TRIM(B10),"',",IF(TRIM(C10)="","NULL","'"&TRIM(C10)&"'"),",'",TRIM(D10),"',",IF(TRIM(E10)="","NULL","'"&TRIM(E10)&"'"),",",IF(TRIM(G10)="","NULL","'"&TRIM(G10)&"'"),",",IF(TRIM(H10)="","NULL","'"&TRIM(H10)&"'"),",", IF(TRIM(I10)="","NULL",TRIM(I10)),",",IF(TRIM(J10)="","NULL","'"&TEXT(J10,"yyyy-mm-dd")&"'"),",",IF(TRIM(K10)="","NULL","'"&TEXT(K10,"yyyy-mm-dd")&"'"),",","USER, CURRENT_TIMESTAMP(0));") -> INSERT INTO metadata_reference.file_schema VALUES('CIRC_PORT_PODT','PODT_EXPCT_STAY_LEN_CODE',NULL,'CHAR(3)',NULL,NULL,NULL,NULL,'2025-10-22','9999-12-31',USER, CURRENT_TIMESTAMP(0));
A11: =ETLMetadata!$C11 -> CIRC_PORT_PODT | B11: =ETLMetadata!$E11 -> PODT_AUS_DPRT_DATE | C11: =IF(ISBLANK(ETLMetadata!$J11), "", ETLMetadata!$J11) | D11: =ETLMetadata!$G11 -> DATE | G11: =UPPER($F11) | J11: 45952 | K11: 2958465 | L11: =CONCATENATE("INSERT INTO metadata_reference.file_schema VALUES('",TRIM(A11),"','",TRIM(B11),"',",IF(TRIM(C11)="","NULL","'"&TRIM(C11)&"'"),",'",TRIM(D11),"',",IF(TRIM(E11)="","NULL","'"&TRIM(E11)&"'"),",",IF(TRIM(G11)="","NULL","'"&TRIM(G11)&"'"),",",IF(TRIM(H11)="","NULL","'"&TRIM(H11)&"'"),",", IF(TRIM(I11)="","NULL",TRIM(I11)),",",IF(TRIM(J11)="","NULL","'"&TEXT(J11,"yyyy-mm-dd")&"'"),",",IF(TRIM(K11)="","NULL","'"&TEXT(K11,"yyyy-mm-dd")&"'"),",","USER, CURRENT_TIMESTAMP(0));") -> INSERT INTO metadata_reference.file_schema VALUES('CIRC_PORT_PODT','PODT_AUS_DPRT_DATE',NULL,'DATE',NULL,NULL,NULL,NULL,'2025-10-22','9999-12-31',USER, CURRENT_TIMESTAMP(0));
A12: =ETLMetadata!$C12 -> CIRC_PORT_PODT | B12: =ETLMetadata!$E12 -> PODT_AUS_DPRT_DATE_ORIG | C12: =IF(ISBLANK(ETLMetadata!$J12), "", ETLMetadata!$J12) | D12: =ETLMetadata!$G12 -> INTEGER | G12: =UPPER($F12) | J12: 45952 | K12: 2958465 | L12: =CONCATENATE("INSERT INTO metadata_reference.file_schema VALUES('",TRIM(A12),"','",TRIM(B12),"',",IF(TRIM(C12)="","NULL","'"&TRIM(C12)&"'"),",'",TRIM(D12),"',",IF(TRIM(E12)="","NULL","'"&TRIM(E12)&"'"),",",IF(TRIM(G12)="","NULL","'"&TRIM(G12)&"'"),",",IF(TRIM(H12)="","NULL","'"&TRIM(H12)&"'"),",", IF(TRIM(I12)="","NULL",TRIM(I12)),",",IF(TRIM(J12)="","NULL","'"&TEXT(J12,"yyyy-mm-dd")&"'"),",",IF(TRIM(K12)="","NULL","'"&TEXT(K12,"yyyy-mm-dd")&"'"),",","USER, CURRENT_TIMESTAMP(0));") -> INSERT INTO metadata_reference.file_schema VALUES('CIRC_PORT_PODT','PODT_AUS_DPRT_DATE_ORIG',NULL,'INTEGER',NULL,NULL,NULL,NULL,'2025-10-22','9999-12-31',USER, CURRENT_TIMESTAMP(0));
A13: =ETLMetadata!$C13 -> CIRC_PORT_PODT | B13: =ETLMetadata!$E13 -> PODT_AUS_RTN_DATE | C13: =IF(ISBLANK(ETLMetadata!$J13), "", ETLMetadata!$J13) | D13: =ETLMetadata!$G13 -> DATE | G13: =UPPER($F13) | J13: 45952 | K13: 2958465 | L13: =CONCATENATE("INSERT INTO metadata_reference.file_schema VALUES('",TRIM(A13),"','",TRIM(B13),"',",IF(TRIM(C13)="","NULL","'"&TRIM(C13)&"'"),",'",TRIM(D13),"',",IF(TRIM(E13)="","NULL","'"&TRIM(E13)&"'"),",",IF(TRIM(G13)="","NULL","'"&TRIM(G13)&"'"),",",IF(TRIM(H13)="","NULL","'"&TRIM(H13)&"'"),",", IF(TRIM(I13)="","NULL",TRIM(I13)),",",IF(TRIM(J13)="","NULL","'"&TEXT(J13,"yyyy-mm-dd")&"'"),",",IF(TRIM(K13)="","NULL","'"&TEXT(K13,"yyyy-mm-dd")&"'"),",","USER, CURRENT_TIMESTAMP(0));") -> INSERT INTO metadata_reference.file_schema VALUES('CIRC_PORT_PODT','PODT_AUS_RTN_DATE',NULL,'DATE',NULL,NULL,NULL,NULL,'2025-10-22','9999-12-31',USER, CURRENT_TIMESTAMP(0));
A14: =ETLMetadata!$C14 -> CIRC_PORT_PODT | B14: =ETLMetadata!$E14 -> PODT_AUS_RTN_DATE_ORIG | C14: =IF(ISBLANK(ETLMetadata!$J14), "", ETLMetadata!$J14) | D14: =ETLMetadata!$G14 -> INTEGER | G14: =UPPER($F14) | J14: 45952 | K14: 2958465 | L14: =CONCATENATE("INSERT INTO metadata_reference.file_schema VALUES('",TRIM(A14),"','",TRIM(B14),"',",IF(TRIM(C14)="","NULL","'"&TRIM(C14)&"'"),",'",TRIM(D14),"',",IF(TRIM(E14)="","NULL","'"&TRIM(E14)&"'"),",",IF(TRIM(G14)="","NULL","'"&TRIM(G14)&"'"),",",IF(TRIM(H14)="","NULL","'"&TRIM(H14)&"'"),",", IF(TRIM(I14)="","NULL",TRIM(I14)),",",IF(TRIM(J14)="","NULL","'"&TEXT(J14,"yyyy-mm-dd")&"'"),",",IF(TRIM(K14)="","NULL","'"&TEXT(K14,"yyyy-mm-dd")&"'"),",","USER, CURRENT_TIMESTAMP(0));") -> INSERT INTO metadata_reference.file_schema VALUES('CIRC_PORT_PODT','PODT_AUS_RTN_DATE_ORIG',NULL,'INTEGER',NULL,NULL,NULL,NULL,'2025-10-22','9999-12-31',USER, CURRENT_TIMESTAMP(0));
A15: =ETLMetadata!$C15 -> CIRC_PORT_PODT | B15: =ETLMetadata!$E15 -> PODT_DPRT_CERT_CODE | C15: =IF(ISBLANK(ETLMetadata!$J15), "", ETLMetadata!$J15) | D15: =ETLMetadata!$G15 -> CHAR(3) | G15: =UPPER($F15) | J15: 45952 | K15: 2958465 | L15: =CONCATENATE("INSERT INTO metadata_reference.file_schema VALUES('",TRIM(A15),"','",TRIM(B15),"',",IF(TRIM(C15)="","NULL","'"&TRIM(C15)&"'"),",'",TRIM(D15),"',",IF(TRIM(E15)="","NULL","'"&TRIM(E15)&"'"),",",IF(TRIM(G15)="","NULL","'"&TRIM(G15)&"'"),",",IF(TRIM(H15)="","NULL","'"&TRIM(H15)&"'"),",", IF(TRIM(I15)="","NULL",TRIM(I15)),",",IF(TRIM(J15)="","NULL","'"&TEXT(J15,"yyyy-mm-dd")&"'"),",",IF(TRIM(K15)="","NULL","'"&TEXT(K15,"yyyy-mm-dd")&"'"),",","USER, CURRENT_TIMESTAMP(0));") -> INSERT INTO metadata_reference.file_schema VALUES('CIRC_PORT_PODT','PODT_DPRT_CERT_CODE',NULL,'CHAR(3)',NULL,NULL,NULL,NULL,'2025-10-22','9999-12-31',USER, CURRENT_TIMESTAMP(0));
A16: =ETLMetadata!$C16 -> CIRC_PORT_PODT | B16: =ETLMetadata!$E16 -> PODT_DOV | C16: =IF(ISBLANK(ETLMetadata!$J16), "", ETLMetadata!$J16) | D16: =ETLMetadata!$G16 -> DATE | G16: =UPPER($F16) | J16: 45952 | K16: 2958465 | L16: =CONCATENATE("INSERT INTO metadata_reference.file_schema VALUES('",TRIM(A16),"','",TRIM(B16),"',",IF(TRIM(C16)="","NULL","'"&TRIM(C16)&"'"),",'",TRIM(D16),"',",IF(TRIM(E16)="","NULL","'"&TRIM(E16)&"'"),",",IF(TRIM(G16)="","NULL","'"&TRIM(G16)&"'"),",",IF(TRIM(H16)="","NULL","'"&TRIM(H16)&"'"),",", IF(TRIM(I16)="","NULL",TRIM(I16)),",",IF(TRIM(J16)="","NULL","'"&TEXT(J16,"yyyy-mm-dd")&"'"),",",IF(TRIM(K16)="","NULL","'"&TEXT(K16,"yyyy-mm-dd")&"'"),",","USER, CURRENT_TIMESTAMP(0));") -> INSERT INTO metadata_reference.file_schema VALUES('CIRC_PORT_PODT','PODT_DOV',NULL,'DATE',NULL,NULL,NULL,NULL,'2025-10-22','9999-12-31',USER, CURRENT_TIMESTAMP(0));
A17: =ETLMetadata!$C17 -> CIRC_PORT_PODT | B17: =ETLMetadata!$E17 -> PODT_DOV_ORIG | C17: =IF(ISBLANK(ETLMetadata!$J17), "", ETLMetadata!$J17) | D17: =ETLMetadata!$G17 -> INTEGER | G17: =UPPER($F17) | J17: 45952 | K17: 2958465 | L17: =CONCATENATE("INSERT INTO metadata_reference.file_schema VALUES('",TRIM(A17),"','",TRIM(B17),"',",IF(TRIM(C17)="","NULL","'"&TRIM(C17)&"'"),",'",TRIM(D17),"',",IF(TRIM(E17)="","NULL","'"&TRIM(E17)&"'"),",",IF(TRIM(G17)="","NULL","'"&TRIM(G17)&"'"),",",IF(TRIM(H17)="","NULL","'"&TRIM(H17)&"'"),",", IF(TRIM(I17)="","NULL",TRIM(I17)),",",IF(TRIM(J17)="","NULL","'"&TEXT(J17,"yyyy-mm-dd")&"'"),",",IF(TRIM(K17)="","NULL","'"&TEXT(K17,"yyyy-mm-dd")&"'"),",","USER, CURRENT_TIMESTAMP(0));") -> INSERT INTO metadata_reference.file_schema VALUES('CIRC_PORT_PODT','PODT_DOV_ORIG',NULL,'INTEGER',NULL,NULL,NULL,NULL,'2025-10-22','9999-12-31',USER, CURRENT_TIMESTAMP(0));
... A33: =ETLMetadata!$C33 -> CIRC_RES_RSCB | B33: =ETLMetadata!$E33 -> ENVIRONMENT_ID | C33: =IF(ISBLANK(ETLMetadata!$J33), "", ETLMetadata!$J33) -> Y | D33: =ETLMetadata!$G33 -> CHAR(1) | G33: =UPPER($F33) | J33: 45952 | K33: 2958465 | L33: =CONCATENATE("INSERT INTO metadata_reference.file_schema VALUES('",TRIM(A33),"','",TRIM(B33),"',",IF(TRIM(C33)="","NULL","'"&TRIM(C33)&"'"),",'",TRIM(D33),"',",IF(TRIM(E33)="","NULL","'"&TRIM(E33)&"'"),",",IF(TRIM(G33)="","NULL","'"&TRIM(G33)&"'"),",",IF(TRIM(H33)="","NULL","'"&TRIM(H33)&"'"),",", IF(TRIM(I33)="","NULL",TRIM(I33)),",",IF(TRIM(J33)="","NULL","'"&TEXT(J33,"yyyy-mm-dd")&"'"),",",IF(TRIM(K33)="","NULL","'"&TEXT(K33,"yyyy-mm-dd")&"'"),",","USER, CURRENT_TIMESTAMP(0));") -> INSERT INTO metadata_reference.file_schema VALUES('CIRC_RES_RSCB','ENVIRONMENT_ID','Y','CHAR(1)',NULL,NULL,NULL,NULL,'2025-10-22','9999-12-31',USER, CURRENT_TIMESTAMP(0));
A34: =ETLMetadata!$C34 -> CIRC_RES_RSCB | B34: =ETLMetadata!$E34 -> PERSON_ID | C34: =IF(ISBLANK(ETLMetadata!$J34), "", ETLMetadata!$J34) -> Y | D34: =ETLMetadata!$G34 -> INTEGER | F34: Personal_IdentityInfoIndirect | G34: =UPPER($F34) -> PERSONAL_IDENTITYINFOINDIRECT | J34: 45952 | K34: 2958465 | L34: =CONCATENATE("INSERT INTO metadata_reference.file_schema VALUES('",TRIM(A34),"','",TRIM(B34),"',",IF(TRIM(C34)="","NULL","'"&TRIM(C34)&"'"),",'",TRIM(D34),"',",IF(TRIM(E34)="","NULL","'"&TRIM(E34)&"'"),",",IF(TRIM(G34)="","NULL","'"&TRIM(G34)&"'"),",",IF(TRIM(H34)="","NULL","'"&TRIM(H34)&"'"),",", IF(TRIM(I34)="","NULL",TRIM(I34)),",",IF(TRIM(J34)="","NULL","'"&TEXT(J34,"yyyy-mm-dd")&"'"),",",IF(TRIM(K34)="","NULL","'"&TEXT(K34,"yyyy-mm-dd")&"'"),",","USER, CURRENT_TIMESTAMP(0));") -> INSERT INTO metadata_reference.file_schema VALUES('CIRC_RES_RSCB','PERSON_ID','Y','INTEGER',NULL,'PERSONAL_IDENTITYINFOINDIRECT ',NULL,NULL,'2025-10-22','9999-12-31',USER, CURRENT_TIMESTAMP(0));
A35: =ETLMetadata!$C35 -> CIRC_RES_RSCB | B35: =ETLMetadata!$E35 -> RSCB_DOR | C35: =IF(ISBLANK(ETLMetadata!$J35), "", ETLMetadata!$J35) | D35: =ETLMetadata!$G35 -> DATE | G35: =UPPER($F35) | J35: 45952 | K35: 2958465 | L35: =CONCATENATE("INSERT INTO metadata_reference.file_schema VALUES('",TRIM(A35),"','",TRIM(B35),"',",IF(TRIM(C35)="","NULL","'"&TRIM(C35)&"'"),",'",TRIM(D35),"',",IF(TRIM(E35)="","NULL","'"&TRIM(E35)&"'"),",",IF(TRIM(G35)="","NULL","'"&TRIM(G35)&"'"),",",IF(TRIM(H35)="","NULL","'"&TRIM(H35)&"'"),",", IF(TRIM(I35)="","NULL",TRIM(I35)),",",IF(TRIM(J35)="","NULL","'"&TEXT(J35,"yyyy-mm-dd")&"'"),",",IF(TRIM(K35)="","NULL","'"&TEXT(K35,"yyyy-mm-dd")&"'"),",","USER, CURRENT_TIMESTAMP(0));") -> INSERT INTO metadata_reference.file_schema VALUES('CIRC_RES_RSCB','RSCB_DOR',NULL,'DATE',NULL,NULL,NULL,NULL,'2025-10-22','9999-12-31',USER, CURRENT_TIMESTAMP(0));
A36: =ETLMetadata!$C36 -> CIRC_RES_RSCB | B36: =ETLMetadata!$E36 -> RSCB_DOR_ORIG | C36: =IF(ISBLANK(ETLMetadata!$J36), "", ETLMetadata!$J36) | D36: =ETLMetadata!$G36 -> INTEGER | G36: =UPPER($F36) | J36: 45952 | K36: 2958465 | L36: =CONCATENATE("INSERT INTO metadata_reference.file_schema VALUES('",TRIM(A36),"','",TRIM(B36),"',",IF(TRIM(C36)="","NULL","'"&TRIM(C36)&"'"),",'",TRIM(D36),"',",IF(TRIM(E36)="","NULL","'"&TRIM(E36)&"'"),",",IF(TRIM(G36)="","NULL","'"&TRIM(G36)&"'"),",",IF(TRIM(H36)="","NULL","'"&TRIM(H36)&"'"),",", IF(TRIM(I36)="","NULL",TRIM(I36)),",",IF(TRIM(J36)="","NULL","'"&TEXT(J36,"yyyy-mm-dd")&"'"),",",IF(TRIM(K36)="","NULL","'"&TEXT(K36,"yyyy-mm-dd")&"'"),",","USER, CURRENT_TIMESTAMP(0));") -> INSERT INTO metadata_reference.file_schema VALUES('CIRC_RES_RSCB','RSCB_DOR_ORIG',NULL,'INTEGER',NULL,NULL,NULL,NULL,'2025-10-22','9999-12-31',USER, CURRENT_TIMESTAMP(0));
A37: =ETLMetadata!$C37 -> CIRC_RES_RSCB | B37: =ETLMetadata!$E37 -> PROCESSING_SEQUENCE | C37: =IF(ISBLANK(ETLMetadata!$J37), "", ETLMetadata!$J37) -> Y | D37: =ETLMetadata!$G37 -> SMALLINT | G37: =UPPER($F37) | J37: 45952 | K37: 2958465 | L37: =CONCATENATE("INSERT INTO metadata_reference.file_schema VALUES('",TRIM(A37),"','",TRIM(B37),"',",IF(TRIM(C37)="","NULL","'"&TRIM(C37)&"'"),",'",TRIM(D37),"',",IF(TRIM(E37)="","NULL","'"&TRIM(E37)&"'"),",",IF(TRIM(G37)="","NULL","'"&TRIM(G37)&"'"),",",IF(TRIM(H37)="","NULL","'"&TRIM(H37)&"'"),",", IF(TRIM(I37)="","NULL",TRIM(I37)),",",IF(TRIM(J37)="","NULL","'"&TEXT(J37,"yyyy-mm-dd")&"'"),",",IF(TRIM(K37)="","NULL","'"&TEXT(K37,"yyyy-mm-dd")&"'"),",","USER, CURRENT_TIMESTAMP(0));") -> INSERT INTO metadata_reference.file_schema VALUES('CIRC_RES_RSCB','PROCESSING_SEQUENCE','Y','SMALLINT',NULL,NULL,NULL,NULL,'2025-10-22','9999-12-31',USER, CURRENT_TIMESTAMP(0));
A38: =ETLMetadata!$C38 -> CIRC_RES_RSCB | B38: =ETLMetadata!$E38 -> RSCB_AMR_1 | C38: =IF(ISBLANK(ETLMetadata!$J38), "", ETLMetadata!$J38) | D38: =ETLMetadata!$G38 -> CHAR(4) | G38: =UPPER($F38) | J38: 45952 | K38: 2958465 | L38: =CONCATENATE("INSERT INTO metadata_reference.file_schema VALUES('",TRIM(A38),"','",TRIM(B38),"',",IF(TRIM(C38)="","NULL","'"&TRIM(C38)&"'"),",'",TRIM(D38),"',",IF(TRIM(E38)="","NULL","'"&TRIM(E38)&"'"),",",IF(TRIM(G38)="","NULL","'"&TRIM(G38)&"'"),",",IF(TRIM(H38)="","NULL","'"&TRIM(H38)&"'"),",", IF(TRIM(I38)="","NULL",TRIM(I38)),",",IF(TRIM(J38)="","NULL","'"&TEXT(J38,"yyyy-mm-dd")&"'"),",",IF(TRIM(K38)="","NULL","'"&TEXT(K38,"yyyy-mm-dd")&"'"),",","USER, CURRENT_TIMESTAMP(0));") -> INSERT INTO metadata_reference.file_schema VALUES('CIRC_RES_RSCB','RSCB_AMR_1',NULL,'CHAR(4)',NULL,NULL,NULL,NULL,'2025-10-22','9999-12-31',USER, CURRENT_TIMESTAMP(0));
A39: =ETLMetadata!$C39 -> CIRC_RES_RSCB | B39: =ETLMetadata!$E39 -> RSCB_AMR_2 | C39: =IF(ISBLANK(ETLMetadata!$J39), "", ETLMetadata!$J39) | D39: =ETLMetadata!$G39 -> CHAR(1) | G39: =UPPER($F39) | J39: 45952 | K39: 2958465 | L39: =CONCATENATE("INSERT INTO metadata_reference.file_schema VALUES('",TRIM(A39),"','",TRIM(B39),"',",IF(TRIM(C39)="","NULL","'"&TRIM(C39)&"'"),",'",TRIM(D39),"',",IF(TRIM(E39)="","NULL","'"&TRIM(E39)&"'"),",",IF(TRIM(G39)="","NULL","'"&TRIM(G39)&"'"),",",IF(TRIM(H39)="","NULL","'"&TRIM(H39)&"'"),",", IF(TRIM(I39)="","NULL",TRIM(I39)),",",IF(TRIM(J39)="","NULL","'"&TEXT(J39,"yyyy-mm-dd")&"'"),",",IF(TRIM(K39)="","NULL","'"&TEXT(K39,"yyyy-mm-dd")&"'"),",","USER, CURRENT_TIMESTAMP(0));") -> INSERT INTO metadata_reference.file_schema VALUES('CIRC_RES_RSCB','RSCB_AMR_2',NULL,'CHAR(1)',NULL,NULL,NULL,NULL,'2025-10-22','9999-12-31',USER, CURRENT_TIMESTAMP(0));
A40: =ETLMetadata!$C40 -> CIRC_RES_RSCB | B40: =ETLMetadata!$E40 -> RSCB_AMR_3 | C40: =IF(ISBLANK(ETLMetadata!$J40), "", ETLMetadata!$J40) | D40: =ETLMetadata!$G40 -> CHAR(4) | G40: =UPPER($F40) | J40: 45952 | K40: 2958465 | L40: =CONCATENATE("INSERT INTO metadata_reference.file_schema VALUES('",TRIM(A40),"','",TRIM(B40),"',",IF(TRIM(C40)="","NULL","'"&TRIM(C40)&"'"),",'",TRIM(D40),"',",IF(TRIM(E40)="","NULL","'"&TRIM(E40)&"'"),",",IF(TRIM(G40)="","NULL","'"&TRIM(G40)&"'"),",",IF(TRIM(H40)="","NULL","'"&TRIM(H40)&"'"),",", IF(TRIM(I40)="","NULL",TRIM(I40)),",",IF(TRIM(J40)="","NULL","'"&TEXT(J40,"yyyy-mm-dd")&"'"),",",IF(TRIM(K40)="","NULL","'"&TEXT(K40,"yyyy-mm-dd")&"'"),",","USER, CURRENT_TIMESTAMP(0));") -> INSERT INTO metadata_reference.file_schema VALUES('CIRC_RES_RSCB','RSCB_AMR_3',NULL,'CHAR(4)',NULL,NULL,NULL,NULL,'2025-10-22','9999-12-31',USER, CURRENT_TIMESTAMP(0));
A41: =ETLMetadata!$C41 -> CIRC_RES_RSCB | B41: =ETLMetadata!$E41 -> RSCB_BIRTH_CTRY_CODE | C41: =IF(ISBLANK(ETLMetadata!$J41), "", ETLMetadata!$J41) | D41: =ETLMetadata!$G41 -> CHAR(2) | G41: =UPPER($F41) | J41: 45952 | K41: 2958465 | L41: =CONCATENATE("INSERT INTO metadata_reference.file_schema VALUES('",TRIM(A41),"','",TRIM(B41),"',",IF(TRIM(C41)="","NULL","'"&TRIM(C41)&"'"),",'",TRIM(D41),"',",IF(TRIM(E41)="","NULL","'"&TRIM(E41)&"'"),",",IF(TRIM(G41)="","NULL","'"&TRIM(G41)&"'"),",",IF(TRIM(H41)="","NULL","'"&TRIM(H41)&"'"),",", IF(TRIM(I41)="","NULL",TRIM(I41)),",",IF(TRIM(J41)="","NULL","'"&TEXT(J41,"yyyy-mm-dd")&"'"),",",IF(TRIM(K41)="","NULL","'"&TEXT(K41,"yyyy-mm-dd")&"'"),",","USER, CURRENT_TIMESTAMP(0));") -> INSERT INTO metadata_reference.file_schema VALUES('CIRC_RES_RSCB','RSCB_BIRTH_CTRY_CODE',NULL,'CHAR(2)',NULL,NULL,NULL,NULL,'2025-10-22','9999-12-31',USER, CURRENT_TIMESTAMP(0));
A42: =ETLMetadata!$C42 -> CIRC_RES_RSCB | B42: =ETLMetadata!$E42 -> RSCB_CHNL_CODE | C42: =IF(ISBLANK(ETLMetadata!$J42), "", ETLMetadata!$J42) | D42: =ETLMetadata!$G42 -> CHAR(3) | G42: =UPPER($F42) | J42: 45952 | K42: 2958465 | L42: =CONCATENATE("INSERT INTO metadata_reference.file_schema VALUES('",TRIM(A42),"','",TRIM(B42),"',",IF(TRIM(C42)="","NULL","'"&TRIM(C42)&"'"),",'",TRIM(D42),"',",IF(TRIM(E42)="","NULL","'"&TRIM(E42)&"'"),",",IF(TRIM(G42)="","NULL","'"&TRIM(G42)&"'"),",",IF(TRIM(H42)="","NULL","'"&TRIM(H42)&"'"),",", IF(TRIM(I42)="","NULL",TRIM(I42)),",",IF(TRIM(J42)="","NULL","'"&TEXT(J42,"yyyy-mm-dd")&"'"),",",IF(TRIM(K42)="","NULL","'"&TEXT(K42,"yyyy-mm-dd")&"'"),",","USER, CURRENT_TIMESTAMP(0));") -> INSERT INTO metadata_reference.file_schema VALUES('CIRC_RES_RSCB','RSCB_CHNL_CODE',NULL,'CHAR(3)',NULL,NULL,NULL,NULL,'2025-10-22','9999-12-31',USER, CURRENT_TIMESTAMP(0));
A43: =ETLMetadata!$C43 -> CIRC_RES_RSCB | B43: =ETLMetadata!$E43 -> AMR1_RISL_DTS | C43: =IF(ISBLANK(ETLMetadata!$J43), "", ETLMetadata!$J43) | D43: =ETLMetadata!$G43 -> TIMESTAMP(6) | G43: =UPPER($F43) | J43: 45952 | K43: 2958465 | L43: =CONCATENATE("INSERT INTO metadata_reference.file_schema VALUES('",TRIM(A43),"','",TRIM(B43),"',",IF(TRIM(C43)="","NULL","'"&TRIM(C43)&"'"),",'",TRIM(D43),"',",IF(TRIM(E43)="","NULL","'"&TRIM(E43)&"'"),",",IF(TRIM(G43)="","NULL","'"&TRIM(G43)&"'"),",",IF(TRIM(H43)="","NULL","'"&TRIM(H43)&"'"),",", IF(TRIM(I43)="","NULL",TRIM(I43)),",",IF(TRIM(J43)="","NULL","'"&TEXT(J43,"yyyy-mm-dd")&"'"),",",IF(TRIM(K43)="","NULL","'"&TEXT(K43,"yyyy-mm-dd")&"'"),",","USER, CURRENT_TIMESTAMP(0));") -> INSERT INTO metadata_reference.file_schema VALUES('CIRC_RES_RSCB','AMR1_RISL_DTS',NULL,'TIMESTAMP(6)',NULL,NULL,NULL,NULL,'2025-10-22','9999-12-31',USER, CURRENT_TIMESTAMP(0));
A44: =ETLMetadata!$C44 -> CIRC_RES_RSCB | B44: =ETLMetadata!$E44 -> AMR3_RISL_DTS | C44: =IF(ISBLANK(ETLMetadata!$J44), "", ETLMetadata!$J44) | D44: =ETLMetadata!$G44 -> TIMESTAMP(6) | G44: =UPPER($F44) | J44: 45952 | K44: 2958465 | L44: =CONCATENATE("INSERT INTO metadata_reference.file_schema VALUES('",TRIM(A44),"','",TRIM(B44),"',",IF(TRIM(C44)="","NULL","'"&TRIM(C44)&"'"),",'",TRIM(D44),"',",IF(TRIM(E44)="","NULL","'"&TRIM(E44)&"'"),",",IF(TRIM(G44)="","NULL","'"&TRIM(G44)&"'"),",",IF(TRIM(H44)="","NULL","'"&TRIM(H44)&"'"),",", IF(TRIM(I44)="","NULL",TRIM(I44)),",",IF(TRIM(J44)="","NULL","'"&TEXT(J44,"yyyy-mm-dd")&"'"),",",IF(TRIM(K44)="","NULL","'"&TEXT(K44,"yyyy-mm-dd")&"'"),",","USER, CURRENT_TIMESTAMP(0));") -> INSERT INTO metadata_reference.file_schema VALUES('CIRC_RES_RSCB','AMR3_RISL_DTS',NULL,'TIMESTAMP(6)',NULL,NULL,NULL,NULL,'2025-10-22','9999-12-31',USER, CURRENT_TIMESTAMP(0));
A45: =ETLMetadata!$C45 -> CIRC_RES_RSCB | B45: =ETLMetadata!$E45 -> PARTY_ROLE_ID | C45: =IF(ISBLANK(ETLMetadata!$J45), "", ETLMetadata!$J45) | D45: =ETLMetadata!$G45 -> INTEGER | G45: =UPPER($F45) | J45: 45952 | K45: 2958465 | L45: =CONCATENATE("INSERT INTO metadata_reference.file_schema VALUES('",TRIM(A45),"','",TRIM(B45),"',",IF(TRIM(C45)="","NULL","'"&TRIM(C45)&"'"),",'",TRIM(D45),"',",IF(TRIM(E45)="","NULL","'"&TRIM(E45)&"'"),",",IF(TRIM(G45)="","NULL","'"&TRIM(G45)&"'"),",",IF(TRIM(H45)="","NULL","'"&TRIM(H45)&"'"),",", IF(TRIM(I45)="","NULL",TRIM(I45)),",",IF(TRIM(J45)="","NULL","'"&TEXT(J45,"yyyy-mm-dd")&"'"),",",IF(TRIM(K45)="","NULL","'"&TEXT(K45,"yyyy-mm-dd")&"'"),",","USER, CURRENT_TIMESTAMP(0));") -> INSERT INTO metadata_reference.file_schema VALUES('CIRC_RES_RSCB','PARTY_ROLE_ID',NULL,'INTEGER',NULL,NULL,NULL,NULL,'2025-10-22','9999-12-31',USER, CURRENT_TIMESTAMP(0));
A46: =ETLMetadata!$C46 -> CIRC_RES_RSCB | B46: =ETLMetadata!$E46 -> ERROR_COUNT | C46: =IF(ISBLANK(ETLMetadata!$J46), "", ETLMetadata!$J46) | D46: =ETLMetadata!$G46 -> SMALLINT | G46: =UPPER($F46) | J46: 45952 | K46: 2958465 | L46: =CONCATENATE("INSERT INTO metadata_reference.file_schema VALUES('",TRIM(A46),"','",TRIM(B46),"',",IF(TRIM(C46)="","NULL","'"&TRIM(C46)&"'"),",'",TRIM(D46),"',",IF(TRIM(E46)="","NULL","'"&TRIM(E46)&"'"),",",IF(TRIM(G46)="","NULL","'"&TRIM(G46)&"'"),",",IF(TRIM(H46)="","NULL","'"&TRIM(H46)&"'"),",", IF(TRIM(I46)="","NULL",TRIM(I46)),",",IF(TRIM(J46)="","NULL","'"&TEXT(J46,"yyyy-mm-dd")&"'"),",",IF(TRIM(K46)="","NULL","'"&TEXT(K46,"yyyy-mm-dd")&"'"),",","USER, CURRENT_TIMESTAMP(0));") -> INSERT INTO metadata_reference.file_schema VALUES('CIRC_RES_RSCB','ERROR_COUNT',NULL,'SMALLINT',NULL,NULL,NULL,NULL,'2025-10-22','9999-12-31',USER, CURRENT_TIMESTAMP(0));
... A52: =ETLMetadata!$C52 -> CIRC_RES_RSCV | B52: =ETLMetadata!$E52 -> ENVIRONMENT_ID | C52: =IF(ISBLANK(ETLMetadata!$J52), "", ETLMetadata!$J52) -> Y | D52: =ETLMetadata!$G52 -> CHAR(1) | G52: =UPPER($F52) | J52: 45952 | K52: 2958465 | L52: =CONCATENATE("INSERT INTO metadata_reference.file_schema VALUES('",TRIM(A52),"','",TRIM(B52),"',",IF(TRIM(C52)="","NULL","'"&TRIM(C52)&"'"),",'",TRIM(D52),"',",IF(TRIM(E52)="","NULL","'"&TRIM(E52)&"'"),",",IF(TRIM(G52)="","NULL","'"&TRIM(G52)&"'"),",",IF(TRIM(H52)="","NULL","'"&TRIM(H52)&"'"),",", IF(TRIM(I52)="","NULL",TRIM(I52)),",",IF(TRIM(J52)="","NULL","'"&TEXT(J52,"yyyy-mm-dd")&"'"),",",IF(TRIM(K52)="","NULL","'"&TEXT(K52,"yyyy-mm-dd")&"'"),",","USER, CURRENT_TIMESTAMP(0));") -> INSERT INTO metadata_reference.file_schema VALUES('CIRC_RES_RSCV','ENVIRONMENT_ID','Y','CHAR(1)',NULL,NULL,NULL,NULL,'2025-10-22','9999-12-31',USER, CURRENT_TIMESTAMP(0));
A53: =ETLMetadata!$C53 -> CIRC_RES_RSCV | B53: =ETLMetadata!$E53 -> PERSON_ID | C53: =IF(ISBLANK(ETLMetadata!$J53), "", ETLMetadata!$J53) -> Y | D53: =ETLMetadata!$G53 -> INTEGER | F53: Personal_IdentityInfoIndirect | G53: =UPPER($F53) -> PERSONAL_IDENTITYINFOINDIRECT | J53: 45952 | K53: 2958465 | L53: =CONCATENATE("INSERT INTO metadata_reference.file_schema VALUES('",TRIM(A53),"','",TRIM(B53),"',",IF(TRIM(C53)="","NULL","'"&TRIM(C53)&"'"),",'",TRIM(D53),"',",IF(TRIM(E53)="","NULL","'"&TRIM(E53)&"'"),",",IF(TRIM(G53)="","NULL","'"&TRIM(G53)&"'"),",",IF(TRIM(H53)="","NULL","'"&TRIM(H53)&"'"),",", IF(TRIM(I53)="","NULL",TRIM(I53)),",",IF(TRIM(J53)="","NULL","'"&TEXT(J53,"yyyy-mm-dd")&"'"),",",IF(TRIM(K53)="","NULL","'"&TEXT(K53,"yyyy-mm-dd")&"'"),",","USER, CURRENT_TIMESTAMP(0));") -> INSERT INTO metadata_reference.file_schema VALUES('CIRC_RES_RSCV','PERSON_ID','Y','INTEGER',NULL,'PERSONAL_IDENTITYINFOINDIRECT',NULL,NULL,'2025-10-22','9999-12-31',USER, CURRENT_TIMESTAMP(0));
A54: =ETLMetadata!$C54 -> CIRC_RES_RSCV | B54: =ETLMetadata!$E54 -> RSCV_DOV | C54: =IF(ISBLANK(ETLMetadata!$J54), "", ETLMetadata!$J54) | D54: =ETLMetadata!$G54 -> DATE | G54: =UPPER($F54) | J54: 45952 | K54: 2958465 | L54: =CONCATENATE("INSERT INTO metadata_reference.file_schema VALUES('",TRIM(A54),"','",TRIM(B54),"',",IF(TRIM(C54)="","NULL","'"&TRIM(C54)&"'"),",'",TRIM(D54),"',",IF(TRIM(E54)="","NULL","'"&TRIM(E54)&"'"),",",IF(TRIM(G54)="","NULL","'"&TRIM(G54)&"'"),",",IF(TRIM(H54)="","NULL","'"&TRIM(H54)&"'"),",", IF(TRIM(I54)="","NULL",TRIM(I54)),",",IF(TRIM(J54)="","NULL","'"&TEXT(J54,"yyyy-mm-dd")&"'"),",",IF(TRIM(K54)="","NULL","'"&TEXT(K54,"yyyy-mm-dd")&"'"),",","USER, CURRENT_TIMESTAMP(0));") -> INSERT INTO metadata_reference.file_schema VALUES('CIRC_RES_RSCV','RSCV_DOV',NULL,'DATE',NULL,NULL,NULL,NULL,'2025-10-22','9999-12-31',USER, CURRENT_TIMESTAMP(0));
A55: =ETLMetadata!$C55 -> CIRC_RES_RSCV | B55: =ETLMetadata!$E55 -> RSCV_DOV_ORIG | C55: =IF(ISBLANK(ETLMetadata!$J55), "", ETLMetadata!$J55) | D55: =ETLMetadata!$G55 -> INTEGER | G55: =UPPER($F55) | J55: 45952 | K55: 2958465 | L55: =CONCATENATE("INSERT INTO metadata_reference.file_schema VALUES('",TRIM(A55),"','",TRIM(B55),"',",IF(TRIM(C55)="","NULL","'"&TRIM(C55)&"'"),",'",TRIM(D55),"',",IF(TRIM(E55)="","NULL","'"&TRIM(E55)&"'"),",",IF(TRIM(G55)="","NULL","'"&TRIM(G55)&"'"),",",IF(TRIM(H55)="","NULL","'"&TRIM(H55)&"'"),",", IF(TRIM(I55)="","NULL",TRIM(I55)),",",IF(TRIM(J55)="","NULL","'"&TEXT(J55,"yyyy-mm-dd")&"'"),",",IF(TRIM(K55)="","NULL","'"&TEXT(K55,"yyyy-mm-dd")&"'"),",","USER, CURRENT_TIMESTAMP(0));") -> INSERT INTO metadata_reference.file_schema VALUES('CIRC_RES_RSCV','RSCV_DOV_ORIG',NULL,'INTEGER',NULL,NULL,NULL,NULL,'2025-10-22','9999-12-31',USER, CURRENT_TIMESTAMP(0));
A56: =ETLMetadata!$C56 -> CIRC_RES_RSCV | B56: =ETLMetadata!$E56 -> PROCESSING_SEQUENCE | C56: =IF(ISBLANK(ETLMetadata!$J56), "", ETLMetadata!$J56) -> Y | D56: =ETLMetadata!$G56 -> SMALLINT | G56: =UPPER($F56) | J56: 45952 | K56: 2958465 | L56: =CONCATENATE("INSERT INTO metadata_reference.file_schema VALUES('",TRIM(A56),"','",TRIM(B56),"',",IF(TRIM(C56)="","NULL","'"&TRIM(C56)&"'"),",'",TRIM(D56),"',",IF(TRIM(E56)="","NULL","'"&TRIM(E56)&"'"),",",IF(TRIM(G56)="","NULL","'"&TRIM(G56)&"'"),",",IF(TRIM(H56)="","NULL","'"&TRIM(H56)&"'"),",", IF(TRIM(I56)="","NULL",TRIM(I56)),",",IF(TRIM(J56)="","NULL","'"&TEXT(J56,"yyyy-mm-dd")&"'"),",",IF(TRIM(K56)="","NULL","'"&TEXT(K56,"yyyy-mm-dd")&"'"),",","USER, CURRENT_TIMESTAMP(0));") -> INSERT INTO metadata_reference.file_schema VALUES('CIRC_RES_RSCV','PROCESSING_SEQUENCE','Y','SMALLINT',NULL,NULL,NULL,NULL,'2025-10-22','9999-12-31',USER, CURRENT_TIMESTAMP(0));
A57: =ETLMetadata!$C57 -> CIRC_RES_RSCV | B57: =ETLMetadata!$E57 -> RSCV_AMR_1 | C57: =IF(ISBLANK(ETLMetadata!$J57), "", ETLMetadata!$J57) | D57: =ETLMetadata!$G57 -> CHAR(4) | G57: =UPPER($F57) | J57: 45952 | K57: 2958465 | L57: =CONCATENATE("INSERT INTO metadata_reference.file_schema VALUES('",TRIM(A57),"','",TRIM(B57),"',",IF(TRIM(C57)="","NULL","'"&TRIM(C57)&"'"),",'",TRIM(D57),"',",IF(TRIM(E57)="","NULL","'"&TRIM(E57)&"'"),",",IF(TRIM(G57)="","NULL","'"&TRIM(G57)&"'"),",",IF(TRIM(H57)="","NULL","'"&TRIM(H57)&"'"),",", IF(TRIM(I57)="","NULL",TRIM(I57)),",",IF(TRIM(J57)="","NULL","'"&TEXT(J57,"yyyy-mm-dd")&"'"),",",IF(TRIM(K57)="","NULL","'"&TEXT(K57,"yyyy-mm-dd")&"'"),",","USER, CURRENT_TIMESTAMP(0));") -> INSERT INTO metadata_reference.file_schema VALUES('CIRC_RES_RSCV','RSCV_AMR_1',NULL,'CHAR(4)',NULL,NULL,NULL,NULL,'2025-10-22','9999-12-31',USER, CURRENT_TIMESTAMP(0));
A58: =ETLMetadata!$C58 -> CIRC_RES_RSCV | B58: =ETLMetadata!$E58 -> RSCV_AMR_2 | C58: =IF(ISBLANK(ETLMetadata!$J58), "", ETLMetadata!$J58) | D58: =ETLMetadata!$G58 -> CHAR(1) | G58: =UPPER($F58) | J58: 45952 | K58: 2958465 | L58: =CONCATENATE("INSERT INTO metadata_reference.file_schema VALUES('",TRIM(A58),"','",TRIM(B58),"',",IF(TRIM(C58)="","NULL","'"&TRIM(C58)&"'"),",'",TRIM(D58),"',",IF(TRIM(E58)="","NULL","'"&TRIM(E58)&"'"),",",IF(TRIM(G58)="","NULL","'"&TRIM(G58)&"'"),",",IF(TRIM(H58)="","NULL","'"&TRIM(H58)&"'"),",", IF(TRIM(I58)="","NULL",TRIM(I58)),",",IF(TRIM(J58)="","NULL","'"&TEXT(J58,"yyyy-mm-dd")&"'"),",",IF(TRIM(K58)="","NULL","'"&TEXT(K58,"yyyy-mm-dd")&"'"),",","USER, CURRENT_TIMESTAMP(0));") -> INSERT INTO metadata_reference.file_schema VALUES('CIRC_RES_RSCV','RSCV_AMR_2',NULL,'CHAR(1)',NULL,NULL,NULL,NULL,'2025-10-22','9999-12-31',USER, CURRENT_TIMESTAMP(0));
A59: =ETLMetadata!$C59 -> CIRC_RES_RSCV | B59: =ETLMetadata!$E59 -> RSCV_AMR_3 | C59: =IF(ISBLANK(ETLMetadata!$J59), "", ETLMetadata!$J59) | D59: =ETLMetadata!$G59 -> CHAR(4) | G59: =UPPER($F59) | J59: 45952 | K59: 2958465 | L59: =CONCATENATE("INSERT INTO metadata_reference.file_schema VALUES('",TRIM(A59),"','",TRIM(B59),"',",IF(TRIM(C59)="","NULL","'"&TRIM(C59)&"'"),",'",TRIM(D59),"',",IF(TRIM(E59)="","NULL","'"&TRIM(E59)&"'"),",",IF(TRIM(G59)="","NULL","'"&TRIM(G59)&"'"),",",IF(TRIM(H59)="","NULL","'"&TRIM(H59)&"'"),",", IF(TRIM(I59)="","NULL",TRIM(I59)),",",IF(TRIM(J59)="","NULL","'"&TEXT(J59,"yyyy-mm-dd")&"'"),",",IF(TRIM(K59)="","NULL","'"&TEXT(K59,"yyyy-mm-dd")&"'"),",","USER, CURRENT_TIMESTAMP(0));") -> INSERT INTO metadata_reference.file_schema VALUES('CIRC_RES_RSCV','RSCV_AMR_3',NULL,'CHAR(4)',NULL,NULL,NULL,NULL,'2025-10-22','9999-12-31',USER, CURRENT_TIMESTAMP(0));
A60: =ETLMetadata!$C60 -> CIRC_RES_RSCV | B60: =ETLMetadata!$E60 -> RSCV_AUST_CTZN_VLD_IND | C60: =IF(ISBLANK(ETLMetadata!$J60), "", ETLMetadata!$J60) | D60: =ETLMetadata!$G60 -> CHAR(1) | G60: =UPPER($F60) | J60: 45952 | K60: 2958465 | L60: =CONCATENATE("INSERT INTO metadata_reference.file_schema VALUES('",TRIM(A60),"','",TRIM(B60),"',",IF(TRIM(C60)="","NULL","'"&TRIM(C60)&"'"),",'",TRIM(D60),"',",IF(TRIM(E60)="","NULL","'"&TRIM(E60)&"'"),",",IF(TRIM(G60)="","NULL","'"&TRIM(G60)&"'"),",",IF(TRIM(H60)="","NULL","'"&TRIM(H60)&"'"),",", IF(TRIM(I60)="","NULL",TRIM(I60)),",",IF(TRIM(J60)="","NULL","'"&TEXT(J60,"yyyy-mm-dd")&"'"),",",IF(TRIM(K60)="","NULL","'"&TEXT(K60,"yyyy-mm-dd")&"'"),",","USER, CURRENT_TIMESTAMP(0));") -> INSERT INTO metadata_reference.file_schema VALUES('CIRC_RES_RSCV','RSCV_AUST_CTZN_VLD_IND',NULL,'CHAR(1)',NULL,NULL,NULL,NULL,'2025-10-22','9999-12-31',USER, CURRENT_TIMESTAMP(0));
...

Sheet SNFMetadata
A1: Source System Name | B1: Table Name Source (DL) | C1: Column Name Source (DL) | D1: Data Type DL | E1: Table Name Target- Snowflake STG | F1: Column Name Target- Snowflake STG | G1: Data Type STG | H1: Table Name Target- Snowflake SRC | I1: Column Name Target- Snowflake SRC | J1: Data Type (Snowflake) SRC | K1: INFO-Data Type (Source) | L1: INFO-Format (Source) | M1: transformation rule for STG Views | N1: PK | O1: Source Security Classificaiton | P1: Include Flag | Q1: INFO-start_date | R1: INFO-end_date | S1: INFO-update_user | T1: INFO-update_timestamp | U1: INFO-View Name STG | V1: Stiching Required
A2: =TRIM(ETLMetadata!$B2) -> CLK | B2: =TRIM(ETLMetadata!$C2) -> CIRC_PORT_PODT | C2: =TRIM(ETLMetadata!$F2) -> EXTRACT_DATE | D2: =TRIM(ETLMetadata!$H2) -> StringType() | E2: =CONCATENATE($A2,"_",B2) -> CLK_CIRC_PORT_PODT | F2: =IF($C2="Start_Date","STRT_DT", IF($C2="End_Date","END_DT", IF($C2="Record_Deleted_Flag","RCRD_DEL_IND", IF($C2="IsDeleted","RCRD_DEL_IND", $C2 )))) -> EXTRACT_DATE | G2: VARCHAR | H2: =CONCATENATE($A2,"_",$B2) -> CLK_CIRC_PORT_PODT | I2: =IF($C2="Start_Date","STRT_DT", IF($C2="End_Date","END_DT", IF($C2="Record_Deleted_Flag","RCRD_DEL_IND", IF($C2="IsDeleted","RCRD_DEL_IND", $C2 )))) -> EXTRACT_DATE | J2: =IF(LEFT(TRIM($K2),7)="VARCHAR","VARCHAR", IF(LEFT(TRIM($K2),4)="CHAR","VARCHAR", IF(TRIM($K2)="TIMESTAMP(6)","TIMESTAMP", IF(TRIM($K2)="DATE","DATE", IF(TRIM($K2)="BYTEINT","SMALLINT", IF(TRIM($K2)="SMALLINT","SMALLINT", IF(TRIM($K2)="INTEGER","INTEGER", IF(TRIM($K2)="BIGINT","INTEGER", IF(LEFT(TRIM($K2),7)="DECIMAL",TRIM($K2), IF(TRIM($K2)="BOOLEAN","BOOLEAN", IF(TRIM($K2)="DOUBLE","DOUBLE", IF(TRIM($K2)="FLOAT","FLOAT", IF(TRIM($K2)="REAL","REAL", IF(LEFT(TRIM($K2),6)="STRUCT","VARIANT", IF(LEFT(TRIM($K2),5)="ARRAY","VARIANT", IF(LEFT(TRIM($K2),3)="MAP","VARIANT", IF(LEFT(TRIM($K2),3)="ROW","VARIANT", "NONE" ))))))))))))))))) -> DATE | K2: =TRIM(ETLMetadata!$G2) -> DATE | L2: =TRIM(ETLMetadata!$I2) -> YYYY-MM-DD | M2: =IF(LEFT($K2,7)="VARCHAR","NULLIF(TRIM("&$I2&"),'')", IF(LEFT($K2,4)="CHAR","NULLIF(TRIM("&$I2&"),'')", IF(LEFT($K2,7)="DECIMAL","CAST(NULLIF(TRIM("&$I2&"),'') AS "&$K2&")", IF($K2="TIMESTAMP(6)","TO_TIMESTAMP_NTZ(NULLIF(TRIM("&$I2&"),''),'YYYY-MM-DD HH24:MI:SS.FF6')", IF($K2="DATE","TO_DATE(NULLIF(TRIM("&$I2&"),'') , 'YYYY-MM-DD')", IF($K2="BIGINT","CAST(NULLIF(TRIM("&I2&"),'') AS INTEGER)", IF($K2="BYTEINT","CAST(NULLIF(TRIM("&I2&"),'') AS SMALLINT)", IF($K2="SMALLINT","CAST(NULLIF(TRIM("&I2&"),'') AS SMALLINT)", IF($K2="INTEGER","CAST(NULLIF(TRIM("&I2&"),'') AS INTEGER)", IF($K2="BOOLEAN","CAST(NULLIF(TRIM("&I2&"),'') AS BOOLEAN)", IF($K2="DOUBLE","CAST(NULLIF(TRIM("&I2&"),'') AS DOUBLE)", IF($K2="FLOAT","CAST(NULLIF(TRIM("&I2&"),'') AS FLOAT)", IF($K2="REAL","CAST(NULLIF(TRIM("&I2&"),'') AS REAL)", IF(OR($K2="STRUCT",$K2="ARRAY",$K2="MAP",$K2="ROW"),"CAST(NULLIF(TRIM("&I2&"),'') AS VARIANT)", "NONE" )))))))))))))) -> TO_DATE(NULLIF(TRIM(EXTRACT_DATE),'') , 'YYYY-MM-DD') | N2: =TRIM(ETLMetadata!$J2) | O2: =IF(TRIM(Classification!$G2)="","NOT CONFIDENTIAL",TRIM(Classification!$G2)) -> NOT CONFIDENTIAL | P2: =IF($C2="Start_Date","N", IF($C2="End_Date","N", IF($C2="Record_Deleted_Flag","N", IF($C2="IsDeleted","N", "Y" )))) -> Y | Q2: sysdate() | R2: 2958465 | S2: migration_pipeline | T2: current_timestamp() | U2: =CONCATENATE(A2,"_",B2,"_V") -> CLK_CIRC_PORT_PODT_V | V2: N
